Workbook

Sheet Phase Test Wave
A1: Phase Test Wave — 6 months
B2: Profit Margin: | C2: =Summary!$B$5 -> 0.35 | E2: Nego Buffer: | F2: =Summary!$B$6 -> 0
A4: # | B4: Skill | C4: Level | D4: Location | E4: $/Month | F4: Onsite | G4: Travel | H4: Month 1 | I4: Month 2 | J4: Month 3 | K4: Month 4 | L4: Month 5 | M4: Month 6 | N4: Total MM | O4: Salary Cost | P4: Overhead | Q4: OH% | R4: Total Cost | S4: Selling Price | T4: SP/MM | U4: Hourly | V4: Ovr $/Hr | W4: Comments | X4: Group
B6: TOTALS
B8: LOGISTICS BREAKDOWN
B9: Item | C9: Description | D9: Amount
B10: Per-diem | C10: Travel MM x $50 x 30d | D10: =(0)*50*30 -> 0
B11: Accommodation | C11: Travel MM x $80 x 30d | D11: =(0)*80*30 -> 0
B12: Conveyance | C12: Travel MM x $20 x 21d | D12: =(0)*20*21 -> 0
B13: Air Fare | C13: Travel Res x $450 x 6 trips | D13: =(0)*450*6 -> 0
B14: Visa & Medical | C14: Travel Res x $400 x 6 trips | D14: =(0)*400*6 -> 0
B15: Contingency | C15: 5% of subtotal | D15: =(D10+D11+D12+D13+D14)*5/100 -> 0
B16: TOTAL LOGISTICS | D16: =D10+D11+D12+D13+D14+D15 -> 0
B18: Resources Selling Price | C18: =S6 -> 0
B19: Wave Selling Price (Resources + Logistics) | C19: =C18+D16 -> 0
B20: Nego Buffer (0%) | C20: =C19*F2 -> 0
B21: WAVE FINAL PRICE | C21: =C19+C20 -> 0
B22: Onsite MM | C22: =0 -> 0
B23: Offshore MM | C23: =N6-C22 -> 0
A25: PHASE RANGES (for Gantt Chart)
A26: Phase Name | B26: Start | C26: End
A27: Prepare | B27: 1.5 | C27: 3
A28: Explore | B28: 2.5 | C28: 5
A29: Realize | B29: 4 | C29: 6

Sheet Summary
A1: YASH Technologies - EstiPro
A2: PROJECT ESTIMATE SUMMARY
A4: PARAMETERS (Edit these to update all wave calculations)
A5: Profit Margin % | B5: 0.35
A6: Nego Buffer % | B6: 0
A8: Project Number | B8: PRJ-0028
A9: Version | B9: v1
A10: Status | B10: draft
A11: Customer Name | B11: Saif Al Ghurair
A12: Project Name | B12: Gantt Test Project
A13: Project Location(s) | B13: —
A14: Technology | B14: SAP S/4HANA
A15: Sub Technology
A16: Project Type | B16: Implementation
A17: Sales Manager | B17: —
A18: CRM ID | B18: —
A19: Description
A20: Version Notes | B20: Initial version with phase ranges
A22: WAVE: Phase Test Wave
A23: Total Man-Months | B23: ='Phase Test Wave'!N6 -> 0
A24: Onsite Man-Months | B24: ='Phase Test Wave'!C22 -> 0
A25: Offshore Man-Months | B25: ='Phase Test Wave'!C23 -> 0
A26: Total Cost to Company | B26: ='Phase Test Wave'!R6 -> 0
A27: Total Logistics | B27: ='Phase Test Wave'!D16 -> 0
A28: Resources Selling Price | B28: ='Phase Test Wave'!C18 -> 0
A29: Wave Selling Price | B29: ='Phase Test Wave'!C19 -> 0
A30: Nego Buffer | B30: ='Phase Test Wave'!C20 -> 0
A31: Wave Final Price | B31: ='Phase Test Wave'!C21 -> 0
A33: OVERALL PROJECT
A34: Total Man-Months | B34: ='Phase Test Wave'!N6 -> 0
A35: Total Onsite MM | B35: ='Phase Test Wave'!C22 -> 0
A36: Total Offshore MM | B36: ='Phase Test Wave'!C23 -> 0
A37: Total Logistics | B37: ='Phase Test Wave'!D16 -> 0
A38: Total Cost to Company | B38: ='Phase Test Wave'!R6 -> 0
A39: Total Resources Price | B39: ='Phase Test Wave'!C18 -> 0
A40: Total Selling Price | B40: ='Phase Test Wave'!C19 -> 0
A41: Total Nego Buffer | B41: ='Phase Test Wave'!C20 -> 0
A42: GRAND TOTAL (Final Price) | B42: ='Phase Test Wave'!C21 -> 0
A44: EFFECTIVE PROFIT MARGIN | B44: 0.0% (Set: 35.0%)
A47: COLOR LEGEND
...

Sheet Gantt Chart
A1: YASH Technologies - EstiPro | Gantt Chart
A3: Wave | B3: Phase | C3: M1 | D3: M2 | E3: M3 | F3: M4 | G3: M5 | H3: M6
A4: Phase Test Wave | B4: Prepare | D4: Prepare | E4: Prepare
B5: Explore | E5: Explore | F5: Explore | G5: Explore
B6: Realize | F6: Realize | G6: Realize | H6: Realize
A9: LEGEND
A10: Prepare
A11: Explore
A12: Realize
A13: Deploy
A14: Go-live
A15: Hypercare
A16: Design
A17: Build
A18: Test
A19: UAT
A20: Support
